Workbook

Sheet crop
C1: Name of the indicator | D1: Yield wheat (grain) (UAA1) | E1: Yield wheat (straw) (UAA1) | F1: Yield barley (grain) (UAA1) | G1: Yield barley (straw) (UAA1) | H1: Yield sugar beet (UAA1) | I1: Yield potato (UAA1) | J1: Yield rapeseed (UAA1) | K1: Yield pea (UAA1) | L1: Yield faba bean (UAA1) | M1: Yield maize (UAA1) | N1: Yield alfalfa (UAA1) | O1: Yield sorghum (UAA1) | P1: Yield TG (UAA1) | Q1: Yield wheat (grain) (UAA2) | R1: Yield wheat (straw) (UAA2) | S1: Yield barley (grain) (UAA2) | T1: Yield barley (straw) (UAA2) | U1: Yield sugar beet (UAA2) | V1: Yield potato (UAA2) | W1: Yield rapeseed (UAA2) | X1: Yield pea (UAA2) | Y1: Yield faba bean (UAA2) | Z1: Yield maize (UAA2) | AA1: Yield alfalfa (UAA2) | AB1: Yield sorghum (UAA2) | AC1: Yield TG (UAA2) | AD1: Yield PG | AE1: Area wheat (UAA1) | AF1: Area barley (UAA1) | AG1: Area sugar beet (UAA1) | AH1: Area potato (UAA1) | AI1: Area rapeseed (UAA1) | AJ1: Area pea (UAA1) | AK1: Area faba bean (UAA1) | AL1: Area maize (UAA1) | AM1: Area alfalfa (UAA1) | AN1: Area sorghum (UAA1) | AO1: Area TG (UAA1) | AP1: Area wheat (UAA2) | AQ1: Area barley (UAA2) | AR1: Area sugar beet (UAA2) | AS1: Area potato (UAA2) | AT1: Area rapeseed (UAA2) | AU1: Area pea (UAA2) | AV1: Area faba bean (UAA2) | AW1: Area maize (UAA2) | AX1: Area alfalfa (UAA2) | AY1: Area sorghum (UAA2) | AZ1: Area TG (UAA2) | BA1: Area PG | BB1: N supply wheat (UAA1) | BC1: N supply barley (UAA1) | BD1: N supply sugar beet (UAA1) | BE1: N supply potato (UAA1) | BF1: N supply rapeseed (UAA1) | BG1: N supply pea (UAA1) | BH1: N supply faba bean (UAA1) | BI1: N supply maize (UAA1) | BJ1: N supply alfalfa (UAA1) | BK1: N supply sorghum (UAA1) | BL1: N supply TG (UAA1) | BM1: N supply wheat (UAA2) | BN1: N supply barley (UAA2) | BO1: N supply sugar beet (UAA2) | BP1: N supply potato (UAA2) | BQ1: N supply rapeseed (UAA2) | BR1: N supply pea (UAA2) | BS1: N supply faba bean (UAA2) | BT1: N supply maize (UAA2) | BU1: N supply alfalfa (UAA2) | BV1: N supply sorghum (UAA2) | BW1: N supply TG (UAA2) | BX1: N supply PG | BY1: TFI wheat (UAA1) | BZ1: TFI barley (UAA1) | CA1: TFI sugar beet (UAA1) | CB1: TFI potato (UAA1) | CC1: TFI rapeseed (UAA1) | CD1: TFI pea (UAA1) | CE1: TFI faba bean (UAA1) | CF1: TFI maize (UAA1) | CG1: TFI alfalfa (UAA1) | CH1: TFI sorghum (UAA1) | CI1: TFI TG (UAA1) | CJ1: TFI wheat (UAA2) | CK1: TFI barley (UAA2) | CL1: TFI sugar beet (UAA2) | CM1: TFI potato (UAA2) | CN1: TFI rapeseed (UAA2) | CO1: TFI pea (UAA2) | CP1: TFI faba bean (UAA2) | CQ1: TFI maize (UAA2) | CR1: TFI alfalfa (UAA2) | CS1: TFI sorghum (UAA2) | CT1: TFI TG (UAA2) | CU1: TFI PG
A2: AEP name | B2: AEP_ID | C2: IndicatorID | D2: =INDEX([1]indicators!$I$2:$I$1491,MATCH(D$1,[1]indicators!$C$2:$C$1491,0),1) -> indCr1.UAA1 | E2: =INDEX([1]indicators!$I$2:$I$1491,MATCH(E$1,[1]indicators!$C$2:$C$1491,0),1) -> indCr2.UAA1 | F2: =INDEX([1]indicators!$I$2:$I$1491,MATCH(F$1,[1]indicators!$C$2:$C$1491,0),1) -> indCr3.UAA1 | G2: =INDEX([1]indicators!$I$2:$I$1491,MATCH(G$1,[1]indicators!$C$2:$C$1491,0),1) -> indCr4.UAA1 | H2: =INDEX([1]indicators!$I$2:$I$1491,MATCH(H$1,[1]indicators!$C$2:$C$1491,0),1) -> indCr5.UAA1 | I2: =INDEX([1]indicators!$I$2:$I$1491,MATCH(I$1,[1]indicators!$C$2:$C$1491,0),1) -> indCr6.UAA1 | J2: =INDEX([1]indicators!$I$2:$I$1491,MATCH(J$1,[1]indicators!$C$2:$C$1491,0),1) -> indCr7.UAA1 | K2: =INDEX([1]indicators!$I$2:$I$1491,MATCH(K$1,[1]indicators!$C$2:$C$1491,0),1) -> indCr8.UAA1 | ... CU2: =INDEX([1]indicators!$I$2:$I$1491,MATCH(CU$1,[1]indicators!$C$2:$C$1491,0),1) -> indCr54
A3: =INDEX([1]AEP!$B$2:$B$113,MATCH($B3,[1]AEP!$C$2:$C$113,0),1) -> Conventional tillage (CT) | B3: C.1.1
A4: =INDEX([1]AEP!$B$2:$B$113,MATCH($B4,[1]AEP!$C$2:$C$113,0),1) -> Reduced tillage (RT) | B4: C.1.2
A5: =INDEX([1]AEP!$B$2:$B$113,MATCH($B5,[1]AEP!$C$2:$C$113,0),1) -> No tillage (NT) | B5: C.1.3 | D5: =1-0.08 -> 0.92 | F5: =1-0.08 -> 0.92 | H5: =1-0.08 -> 0.92 | I5: =1-0.08 -> 0.92 | J5: =1-0.08 -> 0.92 | K5: =1-0.08 -> 0.92 | L5: =1-0.08 -> 0.92 | M5: =1-0.08 -> 0.92 | N5: =1-0.08 -> 0.92 | O5: =1-0.08 -> 0.92 | Q5: 0.92 | S5: 0.92 | U5: 0.92 | V5: 0.92 | W5: 0.92 | X5: 0.92 | Y5: 0.92 | Z5: 0.92 | AA5: 0.92 | AB5: 0.92
A6: =INDEX([1]AEP!$B$2:$B$113,MATCH($B6,[1]AEP!$C$2:$C$113,0),1) -> Fall cover crop destructed before winter | B6: C.2.1 | BD6: 20 | BE6: 20 | BI6: 20 | BK6: 20 | BO6: 20 | BP6: 20 | BT6: 20 | BV6: 20
A7: =INDEX([1]AEP!$B$2:$B$113,MATCH($B7,[1]AEP!$C$2:$C$113,0),1) -> Fall cover crop destructed early spring | B7: C.2.2 | BD7: 20 | BE7: 20 | BI7: 20 | BK7: 20 | BO7: 20 | BP7: 20 | BT7: 20 | BV7: 20
A8: =INDEX([1]AEP!$B$2:$B$113,MATCH($B8,[1]AEP!$C$2:$C$113,0),1) -> Permanent soil cover | B8: C.2.3 | D8: =1-0.26 -> 0.74 | F8: =1-0.26 -> 0.74 | H8: =1-0.26 -> 0.74 | I8: =1-0.26 -> 0.74 | J8: =1-0.26 -> 0.74 | K8: =1-0.26 -> 0.74 | L8: =1-0.26 -> 0.74 | M8: =1-0.26 -> 0.74 | N8: =1-0.26 -> 0.74 | O8: =1-0.26 -> 0.74 | Q8: 0.74 | S8: 0.74 | U8: 0.74 | V8: 0.74 | W8: 0.74 | X8: 0.74 | Y8: 0.74 | Z8: 0.74 | AA8: 0.74 | AB8: 0.74 | BB8: =20/2 -> 10 | BC8: =20/2 -> 10 | BD8: =20/2 -> 10 | BE8: =20/2 -> 10 | BF8: =20/2 -> 10 | BI8: =20/2 -> 10 | BK8: =20/2 -> 10 | BM8: =20/2 -> 10 | BN8: =20/2 -> 10 | BO8: =20/2 -> 10 | BP8: =20/2 -> 10 | BQ8: =20/2 -> 10 | BT8: =20/2 -> 10 | BV8: =20/2 -> 10
A9: =INDEX([1]AEP!$B$2:$B$113,MATCH($B9,[1]AEP!$C$2:$C$113,0),1) -> Straw removal | B9: C.3.1
A10: =INDEX([1]AEP!$B$2:$B$113,MATCH($B10,[1]AEP!$C$2:$C$113,0),1) -> Straw left on soil | B10: C.3.2 | E10: 0 | G10: 0 | R10: 0 | T10: 0 | BB10: =-20/2 -> -10 | BC10: =-20/2 -> -10 | BD10: =-20/2 -> -10 | BE10: =-20/2 -> -10 | BF10: =-20/2 -> -10 | BI10: =-20/2 -> -10 | BK10: =-20/2 -> -10 | BM10: =-20/2 -> -10 | BN10: =-20/2 -> -10 | BO10: =-20/2 -> -10 | BP10: =-20/2 -> -10 | BQ10: =-20/2 -> -10 | BT10: =-20/2 -> -10 | BV10: =-20/2 -> -10
A11: =INDEX([1]AEP!$B$2:$B$113,MATCH($B11,[1]AEP!$C$2:$C$113,0),1) -> On-farm organic fertilizers + input of mineral fertilizer | B11: C.4.1
A12: =INDEX([1]AEP!$B$2:$B$113,MATCH($B12,[1]AEP!$C$2:$C$113,0),1) -> On-farm organic fertilizers only | B12: C.4.2
A13: =INDEX([1]AEP!$B$2:$B$113,MATCH($B13,[1]AEP!$C$2:$C$113,0),1) -> Systematic use of chemical fungicides | B13: C.5.1 | BY13: 3 | BZ13: 1 | CA13: 3 | CB13: 14 | CC13: 1 | CD13: 1 | CE13: 1 | CJ13: 3 | CK13: 1 | CL13: 3 | CM13: 14 | CN13: 1 | CO13: 1 | CP13: 1
A14: =INDEX([1]AEP!$B$2:$B$113,MATCH($B14,[1]AEP!$C$2:$C$113,0),1) -> Sound approach of chemical fungicides | B14: C.5.2 | BY14: 2 | CA14: 2 | CB14: 10 | CJ14: 2 | CL14: 2 | CM14: 10
A15: =INDEX([1]AEP!$B$2:$B$113,MATCH($B15,[1]AEP!$C$2:$C$113,0),1) -> Biocontrol products against diseases | B15: C.5.3 | D15: 0.85 | F15: 0.85 | H15: 0.92 | I15: 0.92 | J15: 0.95 | L15: 0.9 | M15: 0.95 | Q15: 0.85 | S15: 0.85 | U15: 0.92 | V15: 0.92 | W15: 0.95 | Y15: 0.9 | Z15: 0.95 | CA15: 1 | CB15: 14 | CL15: 1 | CM15: 14
A16: =INDEX([1]AEP!$B$2:$B$113,MATCH($B16,[1]AEP!$C$2:$C$113,0),1) -> No direct protection against diseases | B16: C.5.4 | D16: =1-0.15 -> 0.85 | F16: =1-0.15 -> 0.85 | H16: =1-0.15 -> 0.85 | I16: =1-0.15 -> 0.85 | J16: =1-0.15 -> 0.85 | K16: =1-0.15 -> 0.85 | L16: =1-0.15 -> 0.85 | M16: =1-0.15 -> 0.85 | N16: =1-0.15 -> 0.85 | O16: =1-0.15 -> 0.85 | Q16: 0.85 | S16: 0.85 | U16: 0.85 | V16: 0.85 | W16: 0.85 | X16: 0.85 | Y16: 0.85 | Z16: 0.85 | AA16: 0.85 | AB16: 0.85
A17: =INDEX([1]AEP!$B$2:$B$113,MATCH($B17,[1]AEP!$C$2:$C$113,0),1) -> Systematic and sole use of chemical herbicides | B17: C.6.1 | BY17: 2 | BZ17: 1 | CA17: 3 | CB17: 3 | CC17: 2 | CD17: 1 | CE17: 1 | CF17: 2 | CG17: 1 | CH17: 1 | CI17: 1 | CJ17: 2 | CK17: 1 | CL17: 3 | CM17: 3 | CN17: 2 | CO17: 1 | CP17: 1 | CQ17: 2 | CR17: 1 | CS17: 1 | CT17: 1
A18: =INDEX([1]AEP!$B$2:$B$113,MATCH($B18,[1]AEP!$C$2:$C$113,0),1) -> Sound approach of chemical herbicides + mechanical weed control | B18: C.6.2 | BY18: 1 | BZ18: 1 | CA18: 2 | CB18: 1 | CC18: 1 | CD18: 1 | CF18: 1 | CJ18: 1 | CK18: 1 | CL18: 2 | CM18: 1 | CN18: 1 | CO18: 1 | CQ18: 1
A19: =INDEX([1]AEP!$B$2:$B$113,MATCH($B19,[1]AEP!$C$2:$C$113,0),1) -> Sole use of mechanical weed control | B19: C.6.3
A20: =INDEX([1]AEP!$B$2:$B$113,MATCH($B20,[1]AEP!$C$2:$C$113,0),1) -> Systematic use of chemical insecticides / molluscicides / nematicides | B20: C.7.1 | BY20: 1 | CA20: 2 | CB20: 3 | CC20: 3 | CD20: 1 | CE20: 1 | CF20: 1 | CG20: 1 | CJ20: 1 | CL20: 2 | CM20: 3 | CN20: 3 | CO20: 1 | CP20: 1 | CQ20: 1 | CR20: 1
A21: =INDEX([1]AEP!$B$2:$B$113,MATCH($B21,[1]AEP!$C$2:$C$113,0),1) -> Sound approach of chemical insecticides / molluscicides / nematicides | B21: C.7.2 | I21: 0.92 | J21: 0.95 | K21: 0.95 | V21: 0.92 | W21: 0.95 | X21: 0.95 | CA21: 1 | CB21: 2 | CC21: 2 | CF21: 1 | CL21: 1 | CM21: 2 | CN21: 2 | CQ21: 1
A22: =INDEX([1]AEP!$B$2:$B$113,MATCH($B22,[1]AEP!$C$2:$C$113,0),1) -> Biocontrol products (incl. pyrethrin) and other natural control techniques against pests | B22: C.7.3 | H22: 0.9 | I22: 0.85 | J22: 0.9 | K22: 0.9 | U22: 0.9 | V22: 0.85 | W22: 0.9 | X22: 0.9 | CA22: 1 | CB22: 1 | CL22: 1 | CM22: 1
A23: =INDEX([1]AEP!$B$2:$B$113,MATCH($B23,[1]AEP!$C$2:$C$113,0),1) -> No direct protection against animal pests | B23: C.7.4 | H23: 0.8 | I23: 0.6 | J23: 0.8 | K23: 0.85 | L23: 0.9 | N23: 0.95 | U23: 0.8 | V23: 0.6 | W23: 0.8 | X23: 0.85 | Y23: 0.9 | AA23: 0.95
A24: =INDEX([1]AEP!$B$2:$B$113,MATCH($B24,[1]AEP!$C$2:$C$113,0),1) -> High yielding cultivars | B24: C.8.1
A25: =INDEX([1]AEP!$B$2:$B$113,MATCH($B25,[1]AEP!$C$2:$C$113,0),1) -> Resistant cultivars and/or mix of varieties | B25: C.8.2 | D25: =1-0.05 -> 0.95 | F25: =1-0.05 -> 0.95 | H25: =1-0.05 -> 0.95 | I25: =1-0.05 -> 0.95 | J25: =1-0.05 -> 0.95 | K25: =1-0.05 -> 0.95 | L25: =1-0.05 -> 0.95 | M25: =1-0.05 -> 0.95 | N25: =1-0.05 -> 0.95 | O25: =1-0.05 -> 0.95 | Q25: 0.95 | S25: 0.95 | U25: 0.95 | V25: 0.95 | W25: 0.95 | X25: 0.95 | Y25: 0.95 | Z25: 0.95 | AA25: 0.95 | AB25: 0.95
A26: =INDEX([1]AEP!$B$2:$B$113,MATCH($B26,[1]AEP!$C$2:$C$113,0),1) -> Temporary grassland composed of grass | B26: C.9.1
A27: =INDEX([1]AEP!$B$2:$B$113,MATCH($B27,[1]AEP!$C$2:$C$113,0),1) -> Temporary grassland composed of simple grass/legume mixtures | B27: C.9.2
A28: =INDEX([1]AEP!$B$2:$B$113,MATCH($B28,[1]AEP!$C$2:$C$113,0),1) -> Temporary grassland composed of complex grass/legume mixtures | B28: C.9.3
A29: =INDEX([1]AEP!$B$2:$B$113,MATCH($B29,[1]AEP!$C$2:$C$113,0),1) -> No permanent grassland | B29: C.10.1 | BA29: 0
A30: =INDEX([1]AEP!$B$2:$B$113,MATCH($B30,[1]AEP!$C$2:$C$113,0),1) -> Permanent grassland occupy a small percentage of the farm area | B30: C.10.2
A31: =INDEX([1]AEP!$B$2:$B$113,MATCH($B31,[1]AEP!$C$2:$C$113,0),1) -> Permanent grassland occupy a high percentage of the farm area | B31: C.10.3 | BA31: 2
A32: =INDEX([1]AEP!$B$2:$B$113,MATCH($B32,[1]AEP!$C$2:$C$113,0),1) -> Sole crops | B32: C.11.1 | AJ32: 0 | AU32: 0
A33: =INDEX([1]AEP!$B$2:$B$113,MATCH($B33,[1]AEP!$C$2:$C$113,0),1) -> Wheat/pea intercrops | B33: C.11.2 | D33: =1+0.12 -> 1.12 | E33: 0 | K33: 1.12 | Q33: 1.12 | R33: 0 | X33: 1.12 | AE33: 0.5 | AP33: 0.5 | BB33: 5 | BM33: 5
A34: =INDEX([1]AEP!$B$2:$B$113,MATCH($B34,[1]AEP!$C$2:$C$113,0),1) -> CS #1: maize - wheat | B34: C.12.1 | AE34: 0.5 | AF34: 0 | AG34: 0 | AH34: 0 | AI34: 0 | AK34: 0 | AL34: 0.5 | AM34: 0 | AN34: 0 | AO34: 0
A35: =INDEX([1]AEP!$B$2:$B$113,MATCH($B35,[1]AEP!$C$2:$C$113,0),1) -> CS #1: rapeseed - wheat - maize - wheat | B35: C.12.2 | AE35: 0.5 | AF35: 0 | AG35: 0 | AH35: 0 | AI35: 0.25 | AK35: 0 | AL35: 0.25 | AM35: 0 | AN35: 0 | AO35: 0 | BB35: =20/2 -> 10
A36: =INDEX([1]AEP!$B$2:$B$113,MATCH($B36,[1]AEP!$C$2:$C$113,0),1) -> CS #1: maize - wheat - maize - barley | B36: C.12.3 | AE36: 0.25 | AF36: 0.25 | AG36: 0 | AH36: 0 | AI36: 0 | AK36: 0 | AL36: 0.5 | AM36: 0 | AN36: 0 | AO36: 0
A37: =INDEX([1]AEP!$B$2:$B$113,MATCH($B37,[1]AEP!$C$2:$C$113,0),1) -> CS #1: alfalfa (3 years) - maize - wheat | B37: C.12.4 | AE37: 0.2 | AF37: 0 | AG37: 0 | AH37: 0 | AI37: 0 | AK37: 0 | AL37: 0.2 | AM37: 0.6 | AN37: 0 | AO37: 0 | BI37: 30
A38: =INDEX([1]AEP!$B$2:$B$113,MATCH($B38,[1]AEP!$C$2:$C$113,0),1) -> CS #1: faba bean - wheat - rapeseed - maize | B38: C.12.5 | AE38: 0.25 | AF38: 0 | AG38: 0 | AH38: 0 | AI38: 0.25 | AK38: 0.25 | AL38: 0.25 | AM38: 0 | AN38: 0 | AO38: 0 | BB38: 20 | BI38: 20
A39: =INDEX([1]AEP!$B$2:$B$113,MATCH($B39,[1]AEP!$C$2:$C$113,0),1) -> CS #1: grassland (4 years) - maize - maize | B39: C.12.6 | AE39: 0 | AF39: 0 | AG39: 0 | AH39: 0 | AI39: 0 | AK39: 0 | AL39: =2/6 -> 0.33333333 | AM39: 0 | AN39: 0 | AO39: =4/6 -> 0.66666667 | BI39: =(110+30)/2 -> 70
A40: =INDEX([1]AEP!$B$2:$B$113,MATCH($B40,[1]AEP!$C$2:$C$113,0),1) -> CS #1: grassland (3 years) - maize - wheat - barley | B40: C.12.7 | AE40: =1/6 -> 0.16666667 | AF40: =1/6 -> 0.16666667 | AG40: 0 | AH40: 0 | AI40: 0 | AK40: 0 | AL40: =1/6 -> 0.16666667 | AM40: 0 | AN40: 0 | AO40: =3/6 -> 0.5 | BI40: 70
...

Sheet environment
C1: Name of the indicator | D1: Natural enemies (UAA1) | E1: Natural enemies (UAA2) | F1: Natural enemies (PG) | G1: Microbial biomass (UAA1) | H1: Microbial biomass (UAA2) | I1: Microbial biomass (PG) | J1: Soil meso-fauna - nematodes (UAA1) | K1: Soil meso-fauna - nematodes (UAA2) | L1: Soil meso-fauna - nematodes (PG) | M1: Earthworm abundance (UAA1) | N1: Earthworm abundance (UAA2) | O1: Earthworm abundance (PG) | P1: Pollinators (UAA1) | Q1: Pollinators (UAA2) | R1: Pollinators (PG) | S1: Soil Organic Carbon (SOC) (UAA1) | T1: Soil Organic Carbon (SOC) (UAA2) | U1: Soil Organic Carbon (SOC) (PG) | V1: N content (UAA1) | W1: N content (UAA2) | X1: N content (PG) | Y1: P content (UAA1) | Z1: P content (UAA2) | AA1: P content (PG) | AB1: Soil water holding capacity (UAA1) | AC1: Soil water holding capacity (UAA2) | AD1: Soil water holding capacity (PG) | AE1: Soil water infiltration (UAA1) | AF1: Soil water infiltration (UAA2) | AG1: Soil water infiltration (PG) | AH1: Resistance of soil to erosion (UAA1) | AI1: Resistance of soil to erosion (UAA2) | AJ1: Resistance of soil to erosion (PG) | AK1: Water quality pesticides (UAA1) | AL1: Water quality pesticides (UAA2) | AM1: Water quality pesticides (PG) | AN1: Water quality nitrates (UAA1) | AO1: Water quality nitrates (UAA2) | AP1: Water quality nitrates (PG)
A2: AEP name | B2: AEP_ID | C2: IndicatorID | D2: =INDEX([1]indicators!$I$2:$I$1491,MATCH(D$1,[1]indicators!$C$2:$C$1491,0),1) -> indCr55.UAA1 | E2: =INDEX([1]indicators!$I$2:$I$1491,MATCH(E$1,[1]indicators!$C$2:$C$1491,0),1) -> indCr55.UAA2 | F2: =INDEX([1]indicators!$I$2:$I$1491,MATCH(F$1,[1]indicators!$C$2:$C$1491,0),1) -> indCr56 | G2: =INDEX([1]indicators!$I$2:$I$1491,MATCH(G$1,[1]indicators!$C$2:$C$1491,0),1) -> indCr57.UAA1 | H2: =INDEX([1]indicators!$I$2:$I$1491,MATCH(H$1,[1]indicators!$C$2:$C$1491,0),1) -> indCr57.UAA2 | I2: =INDEX([1]indicators!$I$2:$I$1491,MATCH(I$1,[1]indicators!$C$2:$C$1491,0),1) -> indCr58 | J2: =INDEX([1]indicators!$I$2:$I$1491,MATCH(J$1,[1]indicators!$C$2:$C$1491,0),1) -> indCr59.UAA1 | K2: =INDEX([1]indicators!$I$2:$I$1491,MATCH(K$1,[1]indicators!$C$2:$C$1491,0),1) -> indCr59.UAA2 | ... AP2: =INDEX([1]indicators!$I$2:$I$1491,MATCH(AP$1,[1]indicators!$C$2:$C$1491,0),1) -> indCr236
A3: =crop!A3 -> Conventional tillage (CT) | B3: =crop!B3 -> C.1.1 | D3: 0.9 | E3: 0.9 | G3: -1 | H3: -1 | J3: 0.8 | K3: 0.8 | M3: -1 | N3: -1 | V3: -0.5 | W3: -0.5 | Y3: -1 | Z3: -1
A4: =crop!A4 -> Reduced tillage (RT) | B4: =crop!B4 -> C.1.2 | D4: 1.01 | E4: 1.01 | G4: 1 | H4: 1 | J4: 1.1 | K4: 1.1 | M4: 1 | N4: 1 | P4: 1.01 | Q4: 1.01 | V4: -0.5 | W4: -0.5 | Y4: 1 | Z4: 1 | AH4: 0.5 | AI4: 0.5
A5: =crop!A5 -> No tillage (NT) | B5: =crop!B5 -> C.1.3 | D5: 1.05 | E5: 1.05 | G5: 2 | H5: 2 | J5: 1.2 | K5: 1.2 | M5: 2 | N5: 2 | P5: 1.03 | Q5: 1.03 | V5: 1 | W5: 1 | Y5: 1 | Z5: 1 | AE5: 0.5 | AF5: 0.5 | AH5: 1 | AI5: 1
A6: =crop!A6 -> Fall cover crop destructed before winter | B6: =crop!B6 -> C.2.1 | J6: 0.9 | K6: 0.9 | V6: 1 | W6: 1
A7: =crop!A7 -> Fall cover crop destructed early spring | B7: =crop!B7 -> C.2.2 | D7: 1.05 | E7: 1.05 | G7: 1 | H7: 1 | J7: 1.05 | K7: 1.05 | M7: 1 | N7: 1 | V7: 1 | W7: 1 | AH7: 0.5 | AI7: 0.5 | AN7: 0.5 | AO7: 0.5
A8: =crop!A8 -> Permanent soil cover | B8: =crop!B8 -> C.2.3 | D8: 1.1 | E8: 1.1 | G8: 2 | H8: 2 | J8: 1.1 | K8: 1.1 | M8: 2 | N8: 2 | S8: 1 | T8: 1 | V8: 2 | W8: 2 | AH8: 2 | AI8: 2 | AN8: 1 | AO8: 1
A9: =crop!A9 -> Straw removal | B9: =crop!B9 -> C.3.1 | G9: -1 | H9: -1 | M9: -1 | N9: -1 | S9: -1 | T9: -1 | V9: -0.5 | W9: -0.5 | Y9: -2 | Z9: -2 | AE9: -1 | AF9: -1
A10: =crop!A10 -> Straw left on soil | B10: =crop!B10 -> C.3.2 | D10: 1.02 | E10: 1.02 | G10: 2 | H10: 2 | J10: 1.02 | K10: 1.02 | M10: 1 | N10: 1 | S10: 0.5 | T10: 0.5 | V10: 1 | W10: 1 | Y10: -1 | Z10: -1 | AE10: 2 | AF10: 2 | AH10: 1 | AI10: 1
A11: =crop!A11 -> On-farm organic fertilizers + input of mineral fertilizer | B11: =crop!B11 -> C.4.1 | S11: 2 | T11: 2 | Y11: 0.5 | Z11: 0.5
A12: =crop!A12 -> On-farm organic fertilizers only | B12: =crop!B12 -> C.4.2 | S12: 1 | T12: 1
A13: =crop!A13 -> Systematic use of chemical fungicides | B13: =crop!B13 -> C.5.1 | G13: -1 | H13: -1 | M13: -1 | N13: -1 | P13: 0.9 | Q13: 0.9 | AK13: -1 | AL13: -1
A14: =crop!A14 -> Sound approach of chemical fungicides | B14: =crop!B14 -> C.5.2 | D14: 1.01 | E14: 1.01 | J14: 1.01 | K14: 1.01 | AK14: -0.5 | AL14: -0.5
A15: =crop!A15 -> Biocontrol products against diseases | B15: =crop!B15 -> C.5.3 | D15: 1.02 | E15: 1.02 | J15: 1.02 | K15: 1.02 | P15: 1.02 | Q15: 1.02
A16: =crop!A16 -> No direct protection against diseases | B16: =crop!B16 -> C.5.4 | D16: 1.03 | E16: 1.03 | G16: 1 | H16: 1 | J16: 1.03 | K16: 1.03 | M16: 1 | N16: 1 | P16: 1.03 | Q16: 1.03 | AK16: =1 -> 1 | AL16: =1 -> 1
A17: =crop!A17 -> Systematic and sole use of chemical herbicides | B17: =crop!B17 -> C.6.1 | D17: 0.9 | E17: 0.9 | J17: 0.9 | K17: 0.9 | P17: 0.9 | Q17: 0.9 | AK17: -1 | AL17: -1
A18: =crop!A18 -> Sound approach of chemical herbicides + mechanical weed control | B18: =crop!B18 -> C.6.2 | D18: 1.01 | E18: 1.01 | G18: -0.5 | H18: -0.5 | J18: 1.01 | K18: 1.01 | P18: 1.01 | Q18: 1.01 | AK18: -0.5 | AL18: -0.5
A19: =crop!A19 -> Sole use of mechanical weed control | B19: =crop!B19 -> C.6.3 | D19: 1.02 | E19: 1.02 | G19: -1 | H19: -1 | J19: 1.02 | K19: 1.02 | M19: -1 | N19: -1 | P19: 1.02 | Q19: 1.02 | V19: -0.5 | W19: -0.5 | AE19: -0.5 | AF19: -0.5 | AH19: -0.5 | AI19: -0.5 | AK19: 1 | AL19: 1
A20: =crop!A20 -> Systematic use of chemical insecticides / molluscicides / nematicides | B20: =crop!B20 -> C.7.1 | D20: 0.8 | E20: 0.8 | J20: 0.8 | K20: 0.8 | M20: -2 | N20: -2 | P20: 0.8 | Q20: 0.8 | AK20: -1 | AL20: -1
A21: =crop!A21 -> Sound approach of chemical insecticides / molluscicides / nematicides | B21: =crop!B21 -> C.7.2 | M21: -0.5 | N21: -0.5 | AK21: -0.5 | AL21: -0.5
A22: =crop!A22 -> Biocontrol products (incl. pyrethrin) and other natural control techniques against pests | B22: =crop!B22 -> C.7.3 | D22: 1.05 | E22: 1.05 | J22: 1.05 | K22: 1.05 | P22: 1.05 | Q22: 1.05
A23: =crop!A23 -> No direct protection against animal pests | B23: =crop!B23 -> C.7.4 | D23: 1.2 | E23: 1.2 | G23: 0.5 | H23: 0.5 | J23: 1.2 | K23: 1.2 | M23: 2 | N23: 2 | P23: 1.2 | Q23: 1.2 | AK23: =1 -> 1 | AL23: =1 -> 1
A24: =crop!A24 -> High yielding cultivars | B24: =crop!B24 -> C.8.1 | Y24: -2 | Z24: -2
A25: =crop!A25 -> Resistant cultivars and/or mix of varieties | B25: =crop!B25 -> C.8.2 | Y25: -0.5 | Z25: -0.5
A26: =crop!A26 -> Temporary grassland composed of grass | B26: =crop!B26 -> C.9.1 | G26: 1 | H26: 1 | M26: 1 | N26: 1 | V26: 1 | W26: 1 | Y26: -1 | Z26: -1 | AB26: 1 | AC26: 1 | AE26: 0.5 | AF26: 0.5
A27: =crop!A27 -> Temporary grassland composed of simple grass/legume mixtures | B27: =crop!B27 -> C.9.2 | D27: 1.02 | E27: 1.02 | G27: 2 | H27: 2 | J27: 1.02 | K27: 1.02 | M27: 2 | N27: 2 | P27: 1.02 | Q27: 1.02 | V27: 1 | W27: 1 | Y27: 1 | Z27: 1 | AB27: 1 | AC27: 1 | AE27: 0.5 | AF27: 0.5
A28: =crop!A28 -> Temporary grassland composed of complex grass/legume mixtures | B28: =crop!B28 -> C.9.3 | D28: 1.05 | E28: 1.05 | G28: 2 | H28: 2 | J28: 1.05 | K28: 1.05 | M28: 2 | N28: 2 | P28: 1.05 | Q28: 1.05 | V28: 1 | W28: 1 | Y28: 2 | Z28: 2 | AB28: 1 | AC28: 1 | AE28: 0.5 | AF28: 0.5
A29: =crop!A29 -> No permanent grassland | B29: =crop!B29 -> C.10.1 | F29: 0.8 | I29: -1 | L29: 0.8 | O29: -1 | R29: 0.8 | X29: -1 | AD29: -1 | AG29: -1
A30: =crop!A30 -> Permanent grassland occupy a small percentage of the farm area | B30: =crop!B30 -> C.10.2 | I30: 1 | O30: 1 | X30: 1 | AA30: 1 | AD30: 1 | AG30: 1
A31: =crop!A31 -> Permanent grassland occupy a high percentage of the farm area | B31: =crop!B31 -> C.10.3 | F31: 1.05 | I31: 2 | L31: 1.05 | O31: 2 | X31: 2 | AA31: 2 | AD31: 1 | AG31: 1
A32: =crop!A32 -> Sole crops | B32: =crop!B32 -> C.11.1 | G32: -1 | H32: -1 | M32: -1 | N32: -1
A33: =crop!A33 -> Wheat/pea intercrops | B33: =crop!B33 -> C.11.2 | D33: 1.1 | E33: 1.1 | G33: 1 | H33: 1 | J33: 1.05 | K33: 1.05 | M33: 1 | N33: 1 | P33: 1.1 | Q33: 1.1 | S33: 1 | T33: 1 | V33: 0.5 | W33: 0.5 | Y33: 0.5 | Z33: 0.5 | AN33: 0.25 | AO33: 0.25
A34: =crop!A34 -> CS #1: maize - wheat | B34: =crop!B34 -> C.12.1 | G34: -1 | Y34: -2
A35: =crop!A35 -> CS #1: rapeseed - wheat - maize - wheat | B35: =crop!B35 -> C.12.2 | D35: 1.02 | J35: 1.02 | P35: 1.02 | Y35: -2 | AE35: 0.5
A36: =crop!A36 -> CS #1: maize - wheat - maize - barley | B36: =crop!B36 -> C.12.3 | D36: 1.02 | J36: 1.02 | P36: 1.02 | Y36: -2 | AE36: 0.5
A37: =crop!A37 -> CS #1: alfalfa (3 years) - maize - wheat | B37: =crop!B37 -> C.12.4 | D37: 1.04 | G37: 1 | J37: 1.04 | M37: 1 | P37: 1.04 | V37: 1 | Y37: -1 | AE37: 0.5 | AN37: =0.5 -> 0.5
A38: =crop!A38 -> CS #1: faba bean - wheat - rapeseed - maize | B38: =crop!B38 -> C.12.5 | D38: 1.04 | G38: 1 | J38: 1.04 | M38: 1 | P38: 1.04 | V38: 1 | Y38: -1 | AE38: 0.5 | AN38: =0.5 -> 0.5
A39: =crop!A39 -> CS #1: grassland (4 years) - maize - maize | B39: =crop!B39 -> C.12.6 | D39: 1.03 | G39: 1 | J39: 1.03 | M39: 1 | P39: 1.03 | S39: 2 | V39: 1 | AB39: 1 | AE39: 0.5 | AH39: 1 | AK39: 1
A40: =crop!A40 -> CS #1: grassland (3 years) - maize - wheat - barley | B40: =crop!B40 -> C.12.7 | D40: 1.03 | G40: 1 | J40: 1.03 | M40: 1 | P40: 1.03 | S40: 2 | V40: 1 | AB40: 1 | AE40: 0.5 | AH40: 1 | AK40: 1
...

Sheet animal
C1: Name of the indicator | D1: Average number of dairy cows | E1: Average number of heifers | F1: Average number of bulls and steers | G1: Average number of calves | H1: Number of culled cows sold | I1: Number of bulls and steers sold | J1: Number of calves sold | K1: Number of non pregnant heifers sold | L1: Number of pregnant heifers sold | M1: Cow culling rate | N1: Heifer conception rate | O1: Cow calving rate | P1: Calf mortality | Q1: Young cattle mortality | R1: Option for herd size | S1: Meat of culled cows | T1: Meat of bulls and steers | U1: Meat of non pregnant heifers | V1: Milk production per dairy cow | W1: Fat content | X1: Protein content | Y1: Somatic cells count | Z1: Animal welfare of cows | AA1: Animal welfare of heifers | AB1: Animal welfare of bulls | AC1: Animal welfare of steers | AD1: Antibiotic use for cows | AE1: Antibiotic use for heifers | AF1: Antibiotic use for bulls | AG1: Antibiotic use for steers | AH1: Anthelmintic use for cows | AI1: Anthelmintic use for heifers | AJ1: Anthelmintic use for bulls | AK1: Anthelmintic use for steers | AL1: Veterinary costs for cows | AM1: Veterinary costs for heifers | AN1: Veterinary costs for bulls | AO1: Veterinary costs for steers | AP1: Insemination costs | AQ1: Water demand for cows | AR1: Water demand for heifers | AS1: Water demand for pregnant heifers | AT1: Water demand for bulls and steers | AU1: Water demand for calves | AV1: Water demand for other uses | AW1: Straw demand for cows | AX1: Straw demand for heifers | AY1: Straw demand for bulls | AZ1: Straw demand for steers | BA1: Manure production of cows | BB1: Manure production of heifers | BC1: Manure production of bulls | BD1: Manure production of steers | BE1: Slurry production of cows | BF1: Slurry production of heifers | BG1: Slurry production of bulls | BH1: Slurry production of steers | BI1: Number of days of grazing | BJ1: Maize silage demand for cows | BK1: Maize silage demand for heifers | BL1: Maize silage demand for bulls | BM1: Maize silage demand for steers | BN1: Grass silage demand for cows | BO1: Grass silage demand for heifers | BP1: Grass silage demand for bulls | BQ1: Grass silage demand for steers | BR1: Alfalfa silage demand for cows | BS1: Alfalfa silage demand for heifers | BT1: Alfalfa silage demand for bulls | BU1: Alfalfa silage demand for steers | BV1: Sorghum silage demand for cows | BW1: Sorghum silage demand for heifers | BX1: Sorghum silage demand for bulls | BY1: Sorghum silage demand for steers | BZ1: Hay demand for cows | CA1: Hay demand for heifers | CB1: Hay demand for bulls | CC1: Hay demand for steers | CD1: Grazed grass demand for cows | CE1: Grazed grass demand for heifers | CF1: Grazed grass demand for bulls | CG1: Grazed grass demand for steers | CH1: Barley demand for cows | CI1: Barley demand for heifers | CJ1: Barley demand for bulls | CK1: Barley demand for steers | CL1: RSM demand for cows | CM1: RSM demand for heifers | CN1: RSM demand for bulls | CO1: RSM demand for steers | CP1: SBM demand for cows | CQ1: SBM demand for heifers | CR1: SBM demand for bulls | CS1: SBM demand for steers | CT1: Faba bean demand for cows | CU1: Faba bean demand for heifers | CV1: Faba bean demand for bulls | CW1: Faba bean demand for steers | CX1: Wheat demand for cows | CY1: Wheat demand for heifers | CZ1: Wheat demand for bulls | DA1: Wheat demand for steers | DB1: Milk replacer demand for cows | DC1: Milk replacer demand for heifers | DD1: Milk replacer demand for bulls | DE1: Milk replacer demand for steers | DF1: Milk demand for cows | DG1: Milk demand for heifers | DH1: Milk demand for bulls | DI1: Milk demand for steers | DJ1: Feed straw demand for cows | DK1: Feed straw demand for heifers | DL1: Feed straw demand for bulls | DM1: Feed straw demand for steers | DN1: Intermediate indicator for indF59 - manure production of cows | DO1: Intermediate indicator for indF59 - manure production of heifers | DP1: Intermediate indicator for indF59 - manure production of bulls | DQ1: Intermediate indicator for indF59 - manure production of steers | DR1: Intermediate indicator for indF59 - slurry production of cows | DS1: Intermediate indicator for indF59 - slurry production of heifers | DT1: Intermediate indicator for indF59 - slurry production of bulls | DU1: Intermediate indicator for indF59 - slurry production of steers
A2: AEP name | B2: AEP_ID | C2: IndicatorID | D2: =INDEX([1]indicators!$I$2:$I$1491,MATCH(D$1,[1]indicators!$C$2:$C$1491,0),1) -> indAn1 | E2: =INDEX([1]indicators!$I$2:$I$1491,MATCH(E$1,[1]indicators!$C$2:$C$1491,0),1) -> indAn2 | F2: =INDEX([1]indicators!$I$2:$I$1491,MATCH(F$1,[1]indicators!$C$2:$C$1491,0),1) -> indAn3 | G2: =INDEX([1]indicators!$I$2:$I$1491,MATCH(G$1,[1]indicators!$C$2:$C$1491,0),1) -> indAn4 | H2: =INDEX([1]indicators!$I$2:$I$1491,MATCH(H$1,[1]indicators!$C$2:$C$1491,0),1) -> indAn5 | I2: =INDEX([1]indicators!$I$2:$I$1491,MATCH(I$1,[1]indicators!$C$2:$C$1491,0),1) -> indAn6 | J2: =INDEX([1]indicators!$I$2:$I$1491,MATCH(J$1,[1]indicators!$C$2:$C$1491,0),1) -> indAn7 | K2: =INDEX([1]indicators!$I$2:$I$1491,MATCH(K$1,[1]indicators!$C$2:$C$1491,0),1) -> indAn8 | ... DU2: =INDEX([1]indicators!$I$2:$I$1491,MATCH(DU$1,[1]indicators!$C$2:$C$1491,0),1) -> indF106
A3: =crop!A3 -> Conventional tillage (CT) | B3: =crop!B3 -> C.1.1
A4: =crop!A4 -> Reduced tillage (RT) | B4: =crop!B4 -> C.1.2
A5: =crop!A5 -> No tillage (NT) | B5: =crop!B5 -> C.1.3
A6: =crop!A6 -> Fall cover crop destructed before winter | B6: =crop!B6 -> C.2.1
A7: =crop!A7 -> Fall cover crop destructed early spring | B7: =crop!B7 -> C.2.2
A8: =crop!A8 -> Permanent soil cover | B8: =crop!B8 -> C.2.3
A9: =crop!A9 -> Straw removal | B9: =crop!B9 -> C.3.1
A10: =crop!A10 -> Straw left on soil | B10: =crop!B10 -> C.3.2
A11: =crop!A11 -> On-farm organic fertilizers + input of mineral fertilizer | B11: =crop!B11 -> C.4.1
A12: =crop!A12 -> On-farm organic fertilizers only | B12: =crop!B12 -> C.4.2
A13: =crop!A13 -> Systematic use of chemical fungicides | B13: =crop!B13 -> C.5.1
A14: =crop!A14 -> Sound approach of chemical fungicides | B14: =crop!B14 -> C.5.2
... A64: =crop!A64 -> Cattle breed is Holstein | B64: =crop!B64 -> A.1.1
A65: =crop!A65 -> Cattle breed is Siemmental | B65: =crop!B65 -> A.1.2 | M65: 0.95 | N65: 1.05 | O65: 1.03 | Q65: 0.97 | S65: 1.06 | T65: 1.15 | U65: 1.14 | V65: 0.75 | W65: 1.05 | X65: 1.03 | Y65: 1.04 | AD65: 1.04 | AL65: 0.9 | AM65: 0.8 | AN65: 0.8 | AO65: 0.8 | AP65: 0.9
A66: =crop!A66 -> Cattle breed is Montbéliarde | B66: =crop!B66 -> A.1.3 | M66: 0.95 | N66: 1.05 | O66: 1.03 | Q66: 0.97 | S66: 1.06 | T66: 1.15 | U66: 1.14 | V66: 0.88 | W66: 1.02 | X66: 1.05 | Y66: 1.04 | AD66: 1.04 | AL66: 0.9 | AM66: 0.8 | AN66: 0.8 | AO66: 0.8 | AP66: 0.9
A67: =crop!A67 -> Initial herd size | B67: =crop!B67 -> A.2.1
A68: =crop!A68 -> 15% increase of initial herd size (no building modification) | B68: =crop!B68 -> A.2.2 | M68: 1.03 | O68: 0.98 | R68: 1.15 | Y68: 1.02 | Z68: 0.9 | AA68: 0.9 | AB68: 0.9 | AC68: 0.9 | AD68: 1.1 | AE68: 1.1 | AF68: 1.1 | AG68: 1.1 | AL68: 1.05 | AM68: 1.03 | AN68: 1.03 | AO68: 1.03
A69: =crop!A69 -> 15% increase of initial herd size (building modification) | B69: =crop!B69 -> A.2.3 | R69: 1.15
A70: =crop!A70 -> 30% increase of initial herd size (building modification) | B70: =crop!B70 -> A.2.4 | R70: 1.3
A71: =crop!A71 -> 15% decrease of initial herd size | B71: =crop!B71 -> A.2.5 | R71: 0.85 | Y71: 0.98 | Z71: 1.1 | AA71: 1.1 | AB71: 1.1 | AC71: 1.1 | AD71: 0.97 | AE71: 0.97 | AF71: 0.97 | AG71: 0.97 | AL71: 0.95 | AM71: 0.97 | AN71: 0.97 | AO71: 0.97
A72: =crop!A72 -> 30% decrease of initial herd size | B72: =crop!B72 -> A.2.6 | R72: 0.7 | Y72: 0.98 | Z72: 1.1 | AA72: 1.1 | AB72: 1.1 | AC72: 1.1 | AD72: 0.97 | AE72: 0.97 | AF72: 0.97 | AG72: 0.97 | AL72: 0.95 | AM72: 0.97 | AN72: 0.97 | AO72: 0.97
A73: =crop!A73 -> Bulls fattened up to 18 months | B73: =crop!B73 -> A.3.1 | J73: 0 | AC73: 0 | AG73: 0 | AK73: 0 | AO73: 0 | AZ73: 0 | BD73: 0 | BH73: 0 | BL73: 3 | BM73: 0 | BP73: 0 | BQ73: 0 | BT73: 0 | BU73: 0 | BX73: 0 | BY73: 0 | CB73: 0.1 | CC73: 0 | CF73: 0 | CG73: 0 | CJ73: 0 | CK73: 0 | CN73: 0 | CO73: 0 | CR73: 0.42 | CS73: 0 | CV73: 0 | CW73: 0 | CZ73: 0.4 | DA73: 0 | DL73: 0 | DM73: 0 | DQ73: 0 | DU73: 0
A74: =crop!A74 -> Castrated males fattened up to 36 months (steer) | B74: =crop!B74 -> A.3.2 | F74: 2.5 | J74: 0 | T74: 1.07 | AB74: 0 | AF74: 0 | AJ74: 0 | AN74: 0 | AY74: 0 | AZ74: 0.5 | BC74: 0 | BG74: 0 | BL74: 0 | BM74: 0 | BP74: 0 | BQ74: 0 | BT74: 0 | BU74: 0 | BX74: 0 | BY74: 0 | CB74: 0 | CC74: 2.5 | CF74: 0 | CG74: 3.4 | CJ74: 0 | CK74: 0 | CN74: 0 | CO74: 0 | CR74: 0 | CS74: 0.06 | CV74: 0 | CW74: 0 | CZ74: 0 | DA74: 0.3 | DL74: 0 | DM74: 0 | DP74: 0 | DT74: 0
A75: =crop!A75 -> Male calves sold at 8 days | B75: =crop!B75 -> A.3.3 | F75: 0 | I75: 0 | T75: 0 | AB75: 0 | AC75: 0 | AF75: 0 | AG75: 0 | AJ75: 0 | AK75: 0 | AN75: 0 | AO75: 0 | AT75: 0 | AU75: 0 | AY75: 0 | AZ75: 0 | BC75: 0 | BD75: 0 | BG75: 0 | BH75: 0 | BL75: 0 | BM75: 0 | BP75: 0 | BQ75: 0 | BT75: 0 | BU75: 0 | BX75: 0 | BY75: 0 | CB75: 0 | CC75: 0 | CF75: 0 | CG75: 0 | CJ75: 0 | CK75: 0 | CN75: 0 | CO75: 0 | CR75: 0 | CS75: 0 | CV75: 0 | CW75: 0 | CZ75: 0 | DA75: 0 | DL75: 0 | DM75: 0 | DP75: 0 | DQ75: 0 | DT75: 0 | DU75: 0
A76: =crop!A76 -> Cows are tied on straw bedding | B76: =crop!B76 -> A.4.1 | AV76: 14 | BE76: 0 | DR76: 0
A77: =crop!A77 -> Housing of cows is cubicles with straw (shallow bedding) | B77: =crop!B77 -> A.4.2 | M77: 0.98 | O77: 1.02 | P77: 0.97 | Q77: 0.98 | V77: 1.01 | Y77: 0.98 | Z77: 1.5 | AD77: 0.98 | AL77: 0.67 | AP77: 0.9 | AQ77: 1.05 | AV77: 17 | BE77: 0 | DR77: 0
A78: =crop!A78 -> Housing of cows is cubicles with slatted floor | B78: =crop!B78 -> A.4.3 | M78: 1.03 | O78: 0.97 | P78: 1.05 | Q78: 1.03 | Y78: 1.03 | Z78: 1.13 | AD78: 1.03 | AL78: 0.67 | AP78: 0.9 | AQ78: 1.05 | AV78: 17 | AW78: 0 | BA78: 0 | DN78: 0
A79: =crop!A79 -> Housing of cows is free-stall (deep bedding) | B79: =crop!B79 -> A.4.4 | M79: 0.98 | O79: 1.03 | P79: 0.95 | Q79: 0.97 | V79: 1.03 | Y79: 1.02 | Z79: 1.65 | AD79: 1.02 | AL79: 0.6 | AP79: 0.81 | AQ79: 1.05 | AV79: 17 | AW79: 1.6 | BA79: 1.1 | BE79: 0 | DN79: 1.1 | DR79: 0
A80: =crop!A80 -> Housing of cows is free-stall slatted floor | B80: =crop!B80 -> A.4.5 | M80: 1.03 | O80: 0.97 | P80: 1.03 | Q80: 1.02 | V80: 0.98 | Y80: 1.03 | Z80: 1.2 | AD80: 1.03 | AL80: 0.6 | AP80: 0.91 | AQ80: 1.05 | AV80: 17 | AW80: 0 | BA80: 0 | DN80: 0
A81: =crop!A81 -> Housing of heifer, bulls and steers is slatted floor | B81: =crop!B81 -> A.5.1 | N81: 0.97 | AX81: 0 | AY81: 0 | AZ81: 0 | BB81: 0 | BC81: 0 | BD81: 0 | DO81: 0 | DP81: 0 | DQ81: 0
A82: =crop!A82 -> Housing of heifer, bulls and steers is shallow bedding | B82: =crop!B82 -> A.5.2 | N82: 1.03 | AA82: 1.61 | AB82: 1.61 | AC82: 1.61 | AM82: 0.8 | AN82: 0.8 | AO82: 0.8 | BF82: 0 | BG82: 0 | BH82: 0 | DS82: 0 | DT82: 0 | DU82: 0
A83: =crop!A83 -> Housing of heifer, bulls and steers is deep bedding | B83: =crop!B83 -> A.5.3 | AA83: 2.01 | AB83: 2.01 | AC83: 2.01 | AM83: 0.5 | AN83: 0.5 | AO83: 0.5 | AX83: 1.6 | AY83: 1.6 | AZ83: 1.6 | BB83: 1.1 | BC83: 1.1 | BD83: 1.1 | BF83: 0 | BG83: 0 | BH83: 0 | DO83: 1.1 | DP83: 1.1 | DQ83: 1.1 | DS83: 0 | DT83: 0 | DU83: 0
A84: =crop!A84 -> Cow feeding system: all year indoor, maize silage & soybean meal supplement | B84: =crop!B84 -> A.6.1 | AH84: 0 | BI84: 0 | BJ84: 5.11 | BN84: 0 | BR84: 0 | BV84: 0 | BZ84: 0.4 | CD84: 0 | CH84: 0 | CL84: 0 | CP84: 0.91 | CT84: 0 | CX84: 1.1 | DJ84: 0
A85: =crop!A85 -> Cow feeding system: all year indoor, sorghum silage & soybean meal supplement | B85: =crop!B85 -> A.6.2 | AH85: 0 | BI85: 0 | BJ85: 0 | BN85: 0 | BR85: 0 | BV85: 3.29 | BZ85: 0.73 | CD85: 0 | CH85: 0 | CL85: 0 | CP85: 0.37 | CT85: 0 | CX85: 3.29 | DJ85: 0
A86: =crop!A86 -> Cow feeding system: all year indoor, sorghum & alfalfa silage | B86: =crop!B86 -> A.6.3 | AH86: 0 | BI86: 0 | BJ86: 0 | BN86: 0 | BR86: 1.83 | BV86: 2.19 | BZ86: 0.44 | CD86: 0 | CH86: 0 | CL86: 0 | CP86: 0 | CT86: 0 | CX86: 3.5 | DJ86: 0
A87: =crop!A87 -> Cow feeding system: all year indoor, maize silage, alfalfa silage & soybean meal supplement | B87: =crop!B87 -> A.6.4 | AH87: 0 | BI87: 0 | BJ87: 2.56 | BN87: 0 | BR87: 2.37 | BV87: 0 | BZ87: 0.44 | CD87: 0 | CH87: 0 | CL87: 0 | CP87: 0.15 | CT87: 0 | CX87: 2.19 | DJ87: 0
A88: =crop!A88 -> Cow feeding system: 4 months grazing & soybean meal supplement | B88: =crop!B88 -> A.6.5 | M88: 0.98 | O88: 1.02 | P88: 0.97 | Q88: 0.98 | V88: 0.94 | W88: 0.95 | X88: 0.93 | Z88: 1.31 | AL88: 0.76 | AP88: 0.84 | AQ88: 0.94 | AW88: =1-(24/24*4/12) -> 0.66666667 | BA88: =1-(24/24*4/12) -> 0.66666667 | BE88: =1-(24/24*4/12) -> 0.66666667 | BI88: =4/12*365 -> 121.66667 | BJ88: 4.27 | BN88: 0 | BR88: 0 | BV88: 0 | BZ88: 0.5 | CD88: 0.84 | CH88: 0 | CL88: 0 | CP88: 0.62 | CT88: 0 | CX88: 1.03 | DJ88: 0 | DN88: =1-(24/24*4/12) -> 0.66666667 | DR88: =1-(24/24*4/12) -> 0.66666667
A89: =crop!A89 -> Cow feeding system: 4 months grazing & rapeseed meal supplement | B89: =crop!B89 -> A.6.6 | M89: 0.98 | O89: 1.02 | P89: 0.97 | Q89: 0.98 | V89: 0.94 | W89: 0.95 | X89: 0.93 | Z89: 1.31 | AL89: 0.76 | AP89: 0.84 | AQ89: 0.94 | AW89: =1-(24/24*4/12) -> 0.66666667 | BA89: =1-(24/24*4/12) -> 0.66666667 | BE89: =1-(24/24*4/12) -> 0.66666667 | BI89: =4/12*365 -> 121.66667 | BJ89: 2.56 | BN89: 1.72 | BR89: 0 | BV89: 0 | BZ89: 0.18 | CD89: 0.84 | CH89: 0 | CL89: 0.55 | CP89: 0 | CT89: 0 | CX89: 1.77 | DJ89: 0 | DN89: =1-(24/24*4/12) -> 0.66666667 | DR89: =1-(24/24*4/12) -> 0.66666667
...

Sheet socioeco
C1: Name of the indicator | D1: Fuel consumption wheat (UAA1) | E1: Fuel consumption barley (UAA1) | F1: Fuel consumption sugar beet (UAA1) | G1: Fuel consumption potato (UAA1) | H1: Fuel consumption rapeseed (UAA1) | I1: Fuel consumption pea (UAA1) | J1: Fuel consumption faba bean (UAA1) | K1: Fuel consumption maize (UAA1) | L1: Fuel consumption alfalfa (UAA1) | M1: Fuel consumption sorghum (UAA1) | N1: Fuel consumption TG (UAA1) | O1: Fuel consumption wheat (UAA2) | P1: Fuel consumption barley (UAA2) | Q1: Fuel consumption sugar beet (UAA2) | R1: Fuel consumption potato (UAA2) | S1: Fuel consumption rapeseed (UAA2) | T1: Fuel consumption pea (UAA2) | U1: Fuel consumption faba bean (UAA2) | V1: Fuel consumption maize (UAA2) | W1: Fuel consumption alfalfa (UAA2) | X1: Fuel consumption sorghum (UAA2) | Y1: Fuel consumption TG (UAA2) | Z1: Fuel consumption PG | AA1: Energy demand for machinery | AB1: Energy demand for milking operations | AC1: Work time wheat (UAA1) - Jan | AD1: Work time wheat (UAA1) - Feb | AE1: Work time wheat (UAA1) - March | AF1: Work time wheat (UAA1) - Apr | AG1: Work time wheat (UAA1) - May | AH1: Work time wheat (UAA1) - June | AI1: Work time wheat (UAA1) - July | AJ1: Work time wheat (UAA1) - Aug | AK1: Work time wheat (UAA1) - Sept | AL1: Work time wheat (UAA1) - Oct | AM1: Work time wheat (UAA1) - Nov | AN1: Work time wheat (UAA1) - Dec | AO1: Work time barley (UAA1) - Jan | AP1: Work time barley (UAA1) - Feb | AQ1: Work time barley (UAA1) - March | AR1: Work time barley (UAA1) - Apr | AS1: Work time barley (UAA1) - May | AT1: Work time barley (UAA1) - June | AU1: Work time barley (UAA1) - July | AV1: Work time barley (UAA1) - Aug | AW1: Work time barley (UAA1) - Sept | AX1: Work time barley (UAA1) - Oct | AY1: Work time barley (UAA1) - Nov | AZ1: Work time barley (UAA1) - Dec | BA1: Work time sugar beet (UAA1) - Jan | BB1: Work time sugar beet (UAA1) - Feb | BC1: Work time sugar beet (UAA1) - March | BD1: Work time sugar beet (UAA1) - Apr | BE1: Work time sugar beet (UAA1) - May | BF1: Work time sugar beet (UAA1) - June | BG1: Work time sugar beet (UAA1) - July | BH1: Work time sugar beet (UAA1) - Aug | BI1: Work time sugar beet (UAA1) - Sept | BJ1: Work time sugar beet (UAA1) - Oct | BK1: Work time sugar beet (UAA1) - Nov | BL1: Work time sugar beet (UAA1) - Dec | BM1: Work time potato (UAA1) - Jan | BN1: Work time potato (UAA1) - Feb | BO1: Work time potato (UAA1) - March | BP1: Work time potato (UAA1) - Apr | BQ1: Work time potato (UAA1) - May | BR1: Work time potato (UAA1) - June | BS1: Work time potato (UAA1) - July | BT1: Work time potato (UAA1) - Aug | BU1: Work time potato (UAA1) - Sept | BV1: Work time potato (UAA1) - Oct | BW1: Work time potato (UAA1) - Nov | BX1: Work time potato (UAA1) - Dec | BY1: Work time rapeseed (UAA1) - Jan | BZ1: Work time rapeseed (UAA1) - Feb | CA1: Work time rapeseed (UAA1) - March | CB1: Work time rapeseed (UAA1) - Apr | CC1: Work time rapeseed (UAA1) - May | CD1: Work time rapeseed (UAA1) - June | CE1: Work time rapeseed (UAA1) - July | CF1: Work time rapeseed (UAA1) - Aug | CG1: Work time rapeseed (UAA1) - Sept | CH1: Work time rapeseed (UAA1) - Oct | CI1: Work time rapeseed (UAA1) - Nov | CJ1: Work time rapeseed (UAA1) - Dec | CK1: Work time pea (UAA1) - Jan | CL1: Work time pea (UAA1) - Feb | CM1: Work time pea (UAA1) - March | CN1: Work time pea (UAA1) - Apr | CO1: Work time pea (UAA1) - May | CP1: Work time pea (UAA1) - June | CQ1: Work time pea (UAA1) - July | CR1: Work time pea (UAA1) - Aug | CS1: Work time pea (UAA1) - Sept | CT1: Work time pea (UAA1) - Oct | CU1: Work time pea (UAA1) - Nov | CV1: Work time pea (UAA1) - Dec | CW1: Work time faba bean (UAA1) - Jan | CX1: Work time faba bean (UAA1) - Feb | CY1: Work time faba bean (UAA1) - March | CZ1: Work time faba bean (UAA1) - Apr | DA1: Work time faba bean (UAA1) - May | DB1: Work time faba bean (UAA1) - June | DC1: Work time faba bean (UAA1) - July | DD1: Work time faba bean (UAA1) - Aug | DE1: Work time faba bean (UAA1) - Sept | DF1: Work time faba bean (UAA1) - Oct | DG1: Work time faba bean (UAA1) - Nov | DH1: Work time faba bean (UAA1) - Dec | DI1: Work time maize (UAA1) - Jan | DJ1: Work time maize (UAA1) - Feb | DK1: Work time maize (UAA1) - March | DL1: Work time maize (UAA1) - Apr | DM1: Work time maize (UAA1) - May | DN1: Work time maize (UAA1) - June | DO1: Work time maize (UAA1) - July | DP1: Work time maize (UAA1) - Aug | DQ1: Work time maize (UAA1) - Sept | DR1: Work time maize (UAA1) - Oct | DS1: Work time maize (UAA1) - Nov | DT1: Work time maize (UAA1) - Dec | DU1: Work time alfalfa (UAA1) - Jan | DV1: Work time alfalfa (UAA1) - Feb | DW1: Work time alfalfa (UAA1) - March | DX1: Work time alfalfa (UAA1) - Apr | DY1: Work time alfalfa (UAA1) - May | DZ1: Work time alfalfa (UAA1) - June | EA1: Work time alfalfa (UAA1) - July | EB1: Work time alfalfa (UAA1) - Aug | EC1: Work time alfalfa (UAA1) - Sept | ED1: Work time alfalfa (UAA1) - Oct | EE1: Work time alfalfa (UAA1) - Nov | EF1: Work time alfalfa (UAA1) - Dec | EG1: Work time sorghum (UAA1) - Jan | EH1: Work time sorghum (UAA1) - Feb | EI1: Work time sorghum (UAA1) - March | EJ1: Work time sorghum (UAA1) - Apr | EK1: Work time sorghum (UAA1) - May | EL1: Work time sorghum (UAA1) - June | EM1: Work time sorghum (UAA1) - July | EN1: Work time sorghum (UAA1) - Aug | EO1: Work time sorghum (UAA1) - Sept | EP1: Work time sorghum (UAA1) - Oct | EQ1: Work time sorghum (UAA1) - Nov | ER1: Work time sorghum (UAA1) - Dec | ES1: Work time TG (UAA1) - Jan | ET1: Work time TG (UAA1) - Feb | EU1: Work time TG (UAA1) - March | EV1: Work time TG (UAA1) - Apr | EW1: Work time TG (UAA1) - May | EX1: Work time TG (UAA1) - June | EY1: Work time TG (UAA1) - July | EZ1: Work time TG (UAA1) - Aug | FA1: Work time TG (UAA1) - Sept | FB1: Work time TG (UAA1) - Oct | FC1: Work time TG (UAA1) - Nov | FD1: Work time TG (UAA1) - Dec | FE1: Work time wheat (UAA2) - Jan | FF1: Work time wheat (UAA2) - Feb | FG1: Work time wheat (UAA2) - March | FH1: Work time wheat (UAA2) - Apr | FI1: Work time wheat (UAA2) - May | FJ1: Work time wheat (UAA2) - June | FK1: Work time wheat (UAA2) - July | FL1: Work time wheat (UAA2) - Aug | FM1: Work time wheat (UAA2) - Sept | FN1: Work time wheat (UAA2) - Oct | FO1: Work time wheat (UAA2) - Nov | FP1: Work time wheat (UAA2) - Dec | FQ1: Work time barley (UAA2) - Jan | FR1: Work time barley (UAA2) - Feb | FS1: Work time barley (UAA2) - March | FT1: Work time barley (UAA2) - Apr | FU1: Work time barley (UAA2) - May | FV1: Work time barley (UAA2) - June | FW1: Work time barley (UAA2) - July | FX1: Work time barley (UAA2) - Aug | FY1: Work time barley (UAA2) - Sept | FZ1: Work time barley (UAA2) - Oct | GA1: Work time barley (UAA2) - Nov | GB1: Work time barley (UAA2) - Dec | GC1: Work time sugar beet (UAA2) - Jan | GD1: Work time sugar beet (UAA2) - Feb | GE1: Work time sugar beet (UAA2) - March | GF1: Work time sugar beet (UAA2) - Apr | GG1: Work time sugar beet (UAA2) - May | GH1: Work time sugar beet (UAA2) - June | GI1: Work time sugar beet (UAA2) - July | GJ1: Work time sugar beet (UAA2) - Aug | GK1: Work time sugar beet (UAA2) - Sept | GL1: Work time sugar beet (UAA2) - Oct | GM1: Work time sugar beet (UAA2) - Nov | GN1: Work time sugar beet (UAA2) - Dec | GO1: Work time potato (UAA2) - Jan | GP1: Work time potato (UAA2) - Feb | GQ1: Work time potato (UAA2) - March | GR1: Work time potato (UAA2) - Apr | GS1: Work time potato (UAA2) - May | GT1: Work time potato (UAA2) - June | GU1: Work time potato (UAA2) - July | GV1: Work time potato (UAA2) - Aug | GW1: Work time potato (UAA2) - Sept | GX1: Work time potato (UAA2) - Oct | GY1: Work time potato (UAA2) - Nov | GZ1: Work time potato (UAA2) - Dec | HA1: Work time rapeseed (UAA2) - Jan | HB1: Work time rapeseed (UAA2) - Feb | HC1: Work time rapeseed (UAA2) - March | HD1: Work time rapeseed (UAA2) - Apr | HE1: Work time rapeseed (UAA2) - May | HF1: Work time rapeseed (UAA2) - June | HG1: Work time rapeseed (UAA2) - July | HH1: Work time rapeseed (UAA2) - Aug | HI1: Work time rapeseed (UAA2) - Sept | HJ1: Work time rapeseed (UAA2) - Oct | HK1: Work time rapeseed (UAA2) - Nov | HL1: Work time rapeseed (UAA2) - Dec | HM1: Work time pea (UAA2) - Jan | HN1: Work time pea (UAA2) - Feb | HO1: Work time pea (UAA2) - March | HP1: Work time pea (UAA2) - Apr | HQ1: Work time pea (UAA2) - May | HR1: Work time pea (UAA2) - June | HS1: Work time pea (UAA2) - July | HT1: Work time pea (UAA2) - Aug | HU1: Work time pea (UAA2) - Sept | HV1: Work time pea (UAA2) - Oct | HW1: Work time pea (UAA2) - Nov | HX1: Work time pea (UAA2) - Dec | HY1: Work time faba bean (UAA2) - Jan | HZ1: Work time faba bean (UAA2) - Feb | IA1: Work time faba bean (UAA2) - March | IB1: Work time faba bean (UAA2) - Apr | IC1: Work time faba bean (UAA2) - May | ID1: Work time faba bean (UAA2) - June | IE1: Work time faba bean (UAA2) - July | IF1: Work time faba bean (UAA2) - Aug | IG1: Work time faba bean (UAA2) - Sept | IH1: Work time faba bean (UAA2) - Oct | II1: Work time faba bean (UAA2) - Nov | IJ1: Work time faba bean (UAA2) - Dec | IK1: Work time maize (UAA2) - Jan | IL1: Work time maize (UAA2) - Feb | IM1: Work time maize (UAA2) - March | IN1: Work time maize (UAA2) - Apr | IO1: Work time maize (UAA2) - May | IP1: Work time maize (UAA2) - June | IQ1: Work time maize (UAA2) - July | IR1: Work time maize (UAA2) - Aug | IS1: Work time maize (UAA2) - Sept | IT1: Work time maize (UAA2) - Oct | IU1: Work time maize (UAA2) - Nov | IV1: Work time maize (UAA2) - Dec | IW1: Work time alfalfa (UAA2) - Jan | IX1: Work time alfalfa (UAA2) - Feb | IY1: Work time alfalfa (UAA2) - March | IZ1: Work time alfalfa (UAA2) - Apr | JA1: Work time alfalfa (UAA2) - May | JB1: Work time alfalfa (UAA2) - June | JC1: Work time alfalfa (UAA2) - July | JD1: Work time alfalfa (UAA2) - Aug | JE1: Work time alfalfa (UAA2) - Sept | JF1: Work time alfalfa (UAA2) - Oct | JG1: Work time alfalfa (UAA2) - Nov | JH1: Work time alfalfa (UAA2) - Dec | JI1: Work time sorghum (UAA2) - Jan | JJ1: Work time sorghum (UAA2) - Feb | JK1: Work time sorghum (UAA2) - March | JL1: Work time sorghum (UAA2) - Apr | JM1: Work time sorghum (UAA2) - May | JN1: Work time sorghum (UAA2) - June | JO1: Work time sorghum (UAA2) - July | JP1: Work time sorghum (UAA2) - Aug | JQ1: Work time sorghum (UAA2) - Sept | JR1: Work time sorghum (UAA2) - Oct | JS1: Work time sorghum (UAA2) - Nov | JT1: Work time sorghum (UAA2) - Dec | JU1: Work time TG (UAA2) - Jan | JV1: Work time TG (UAA2) - Feb | JW1: Work time TG (UAA2) - March | JX1: Work time TG (UAA2) - Apr | JY1: Work time TG (UAA2) - May | JZ1: Work time TG (UAA2) - June | KA1: Work time TG (UAA2) - July | KB1: Work time TG (UAA2) - Aug | KC1: Work time TG (UAA2) - Sept | KD1: Work time TG (UAA2) - Oct | KE1: Work time TG (UAA2) - Nov | KF1: Work time TG (UAA2) - Dec | KG1: Work time PG - Jan | KH1: Work time PG - Feb | KI1: Work time PG - March | KJ1: Work time PG - Apr | KK1: Work time PG - May | KL1: Work time PG - June | KM1: Work time PG - July | KN1: Work time PG - Aug | KO1: Work time PG - Sept | KP1: Work time PG - Oct | KQ1: Work time PG - Nov | KR1: Work time PG - Dec | KS1: Various costs for crop production (UAA1) | KT1: Various costs for crop production (UAA2) | KU1: Susbsidies, 1<sup>st</sup> pillar of the CAP | KV1: Susbsidies, 2<sup>nd</sup> pillar of the CAP | KW1: Investment capacity | KX1: Routine work demand for milking | KY1: Routine work demand for feeding (cows) | KZ1: Routine work demand for feeding (other cattle) | LA1: Routine work demand for manure management (cows) | LB1: Routine work demand for manure management (other cattle) | LC1: Routine work demand for heath & care (cows) | LD1: Routine work demand for heath & care (other cattle) | LE1: Routine work demand for other activities (cows) | LF1: Routine work demand for other activities (other cattle) | LG1: Investment in buildings and agroforestry | LH1: Organic farming | LI1: Complexity of the system
A2: AEP name | B2: AEP_ID | C2: IndicatorID | D2: =INDEX([1]indicators!$I$2:$I$1491,MATCH(D$1,[1]indicators!$C$2:$C$1491,0),1) -> indCr77.UAA1 | E2: =INDEX([1]indicators!$I$2:$I$1491,MATCH(E$1,[1]indicators!$C$2:$C$1491,0),1) -> indCr78.UAA1 | F2: =INDEX([1]indicators!$I$2:$I$1491,MATCH(F$1,[1]indicators!$C$2:$C$1491,0),1) -> indCr79.UAA1 | G2: =INDEX([1]indicators!$I$2:$I$1491,MATCH(G$1,[1]indicators!$C$2:$C$1491,0),1) -> indCr80.UAA1 | H2: =INDEX([1]indicators!$I$2:$I$1491,MATCH(H$1,[1]indicators!$C$2:$C$1491,0),1) -> indCr81.UAA1 | I2: =INDEX([1]indicators!$I$2:$I$1491,MATCH(I$1,[1]indicators!$C$2:$C$1491,0),1) -> indCr82.UAA1 | J2: =INDEX([1]indicators!$I$2:$I$1491,MATCH(J$1,[1]indicators!$C$2:$C$1491,0),1) -> indCr83.UAA1 | K2: =INDEX([1]indicators!$I$2:$I$1491,MATCH(K$1,[1]indicators!$C$2:$C$1491,0),1) -> indCr84.UAA1 | ... LI2: =INDEX([1]indicators!$I$2:$I$1491,MATCH(LI$1,[1]indicators!$C$2:$C$1491,0),1) -> indGl2
A3: =crop!A3 -> Conventional tillage (CT) | B3: =crop!B3 -> C.1.1 | D3: =4.96+24.9+13.97 -> 43.83 | E3: =4.96+24.9+13.97 -> 43.83 | F3: =4.96*3+24.9+9.02 -> 48.8 | G3: =79+24 -> 103 | H3: =4.96*2+24.9+13.97 -> 48.79 | I3: =4.96+24.9+13.97 -> 43.83 | J3: =4.96+24.9+13.97 -> 43.83 | K3: =4.96*3+24.9+9.02 -> 48.8 | L3: =K3/2.5 -> 19.52 | M3: =K3 -> 48.8 | N3: =(4.96*2+24.9+9.02)/3 -> 14.613333 | O3: =4.96+24.9+13.97 -> 43.83 | P3: =4.96+24.9+13.97 -> 43.83 | Q3: =4.96*3+24.9+9.02 -> 48.8 | R3: =79+24 -> 103 | S3: =4.96*2+24.9+13.97 -> 48.79 | T3: =4.96+24.9+13.97 -> 43.83 | U3: =4.96+24.9+13.97 -> 43.83 | V3: =4.96*3+24.9+9.02 -> 48.8 | W3: =V3/2.5 -> 19.52 | X3: =V3 -> 48.8 | Y3: =(4.96*2+24.9+9.02)/3 -> 14.613333 | AL3: =0.31+1.33+0.83 -> 2.47 | AX3: =0.31+1.33+0.83 -> 2.47 | BC3: =0.31+0.67 -> 0.98 | BI3: =0.31*2+1.33 -> 1.95 | BP3: =0.31*3+1.33+2+2 -> 6.26 | BU3: =2*0.31 -> 0.62 | CE3: =0.31*2 -> 0.62 | CF3: =1.33+0.83 -> 2.16 | CT3: =0.31+1.33+0.83 -> 2.47 | DG3: =0.31+1.33+0.83 -> 2.47 | DL3: =0.31*2+1.33+0.67 -> 2.62 | DQ3: 0.31 | EB3: =(0.31*3+1.33+0.67)/2.5 -> 1.172 | EK3: =0.31*2+1.33+0.67 -> 2.62 | EO3: 0.31 | EZ3: =(0.31*2+1.33+0.67)/3 -> 0.87333333 | FN3: =0.31+1.33+0.83 -> 2.47 | FZ3: =0.31+1.33+0.83 -> 2.47 | GE3: =0.31+0.67 -> 0.98 | GK3: =0.31*2+1.33 -> 1.95 | GR3: =0.31*3+1.33+2+2 -> 6.26 | GW3: =2*0.31 -> 0.62 | HG3: =0.31*2 -> 0.62 | HH3: =1.33+0.83 -> 2.16 | HV3: =0.31+1.33+0.83 -> 2.47 | II3: =0.31+1.33+0.83 -> 2.47 | IN3: =0.31*2+1.33+0.67 -> 2.62 | IS3: 0.31 | JD3: =(0.31*3+1.33+0.67)/2.5 -> 1.172 | JM3: =0.31*2+1.33+0.67 -> 2.62 | JQ3: 0.31 | KB3: =(0.31*2+1.33+0.67)/3 -> 0.87333333
A4: =crop!A4 -> Reduced tillage (RT) | B4: =crop!B4 -> C.1.2 | D4: =4.96+13.97 -> 18.93 | E4: =4.96+13.97 -> 18.93 | F4: =4.96*3+9.02 -> 23.9 | G4: =79-24.9+24 -> 78.1 | H4: =4.96*2+13.97 -> 23.89 | I4: =4.96*3+13.97 -> 28.85 | J4: =4.96*3+13.97 -> 28.85 | K4: =4.96*3+9.02 -> 23.9 | L4: =K4/2.5 -> 9.56 | M4: =K4 -> 23.9 | N4: =(4.96*2+9.02)/3 -> 6.3133333 | O4: =4.96+13.97 -> 18.93 | P4: =4.96+13.97 -> 18.93 | Q4: =4.96*3+9.02 -> 23.9 | R4: =79-24.9+24 -> 78.1 | S4: =4.96*2+13.97 -> 23.89 | T4: =4.96*3+13.97 -> 28.85 | U4: =4.96*3+13.97 -> 28.85 | V4: =4.96*3+9.02 -> 23.9 | W4: =V4/2.5 -> 9.56 | X4: =V4 -> 23.9 | Y4: =(4.96*2+9.02)/3 -> 6.3133333 | AL4: =0.31+0.83 -> 1.14 | AX4: =0.31+0.83 -> 1.14 | BC4: =0.31+0.67 -> 0.98 | BI4: =0.31*2 -> 0.62 | BP4: =0.31*3+2+2 -> 4.93 | BU4: =2*0.31 -> 0.62 | CE4: =2*0.31 -> 0.62 | CF4: 0.83 | CT4: =0.31*3+0.83 -> 1.76 | DG4: =0.31*3+0.83 -> 1.76 | DL4: =0.31*2+0.67 -> 1.29 | DQ4: 0.31 | EB4: =(0.31*3+0.67)/2.5 -> 0.64 | EK4: =0.31*2+0.67 -> 1.29 | EO4: 0.31 | EZ4: =(0.31*2+0.67)/3 -> 0.43 | FN4: =0.31+0.83 -> 1.14 | FZ4: =0.31+0.83 -> 1.14 | GE4: =0.31+0.67 -> 0.98 | GK4: =0.31*2 -> 0.62 | GR4: =0.31*3+2+2 -> 4.93 | GW4: =2*0.31 -> 0.62 | HG4: =2*0.31 -> 0.62 | HH4: 0.83 | HV4: =0.31*3+0.83 -> 1.76 | II4: =0.31*3+0.83 -> 1.76 | IN4: =0.31*2+0.67 -> 1.29 | IS4: 0.31 | JD4: =(0.31*3+0.67)/2.5 -> 0.64 | JM4: =0.31*2+0.67 -> 1.29 | JQ4: 0.31 | KB4: =(0.31*2+0.67)/3 -> 0.43 | KS4: 0.9 | KT4: 0.9 | LI4: -0.25
A5: =crop!A5 -> No tillage (NT) | B5: =crop!B5 -> C.1.3 | D5: 6 | E5: 6 | F5: 6 | G5: =24.3+7.1 -> 31.4 | H5: 6 | I5: 6 | J5: 6 | K5: 6 | L5: =K5/2.5 -> 2.4 | M5: 6 | N5: =K5/3 -> 2 | O5: 6 | P5: 6 | Q5: 6 | R5: =24.3+7.1 -> 31.4 | S5: 6 | T5: 6 | U5: 6 | V5: 6 | W5: =V5/2.5 -> 2.4 | X5: 6 | Y5: =V5/3 -> 2 | AL5: 0.42 | AX5: 0.42 | BC5: 0.42 | BP5: =2+2 -> 4 | CF5: 0.42 | CT5: 0.42 | DG5: 0.42 | DL5: 0.42 | EB5: =0.42/2.5 -> 0.168 | EK5: 0.42 | EZ5: =0.42/3 -> 0.14 | FN5: 0.42 | FZ5: 0.42 | GE5: 0.42 | GR5: =2+2 -> 4 | HH5: 0.42 | HV5: 0.42 | II5: 0.42 | IN5: 0.42 | JD5: =0.42/2.5 -> 0.168 | JM5: 0.42 | KB5: =0.42/3 -> 0.14 | KS5: 0.8 | KT5: 0.8 | LI5: -0.5
A6: =crop!A6 -> Fall cover crop destructed before winter | B6: =crop!B6 -> C.2.1 | D6: 6 | E6: 6 | F6: 6 | G6: 6 | H6: 6 | I6: 6 | J6: 6 | K6: 6 | M6: 6 | O6: 6 | P6: 6 | Q6: 6 | R6: 6 | S6: 6 | T6: 6 | U6: 6 | V6: 6 | X6: 6 | AJ6: 0.42 | AV6: 0.42 | BK6: 0.42 | BU6: 0.42 | CF6: 0.42 | CR6: 0.42 | DD6: 0.42 | DR6: 0.42 | EP6: 0.42 | FL6: 0.42 | FX6: 0.42 | GM6: 0.42 | GW6: 0.42 | HH6: 0.42 | HT6: 0.42 | IF6: 0.42 | IT6: 0.42 | JR6: 0.42 | KS6: 1.2 | KT6: 1.2
A7: =crop!A7 -> Fall cover crop destructed early spring | B7: =crop!B7 -> C.2.2 | D7: 6 | E7: 6 | F7: 6 | G7: 6 | H7: 6 | I7: 6 | J7: 6 | K7: 6 | M7: 6 | O7: 6 | P7: 6 | Q7: 6 | R7: 6 | S7: 6 | T7: 6 | U7: 6 | V7: 6 | X7: 6 | AJ7: 0.42 | AV7: 0.42 | BK7: 0.42 | BU7: 0.42 | CF7: 0.42 | CR7: 0.42 | DD7: 0.42 | DR7: 0.42 | EP7: 0.42 | FL7: 0.42 | FX7: 0.42 | GM7: 0.42 | GW7: 0.42 | HH7: 0.42 | HT7: 0.42 | IF7: 0.42 | IT7: 0.42 | JR7: 0.42 | KS7: 1.2 | KT7: 1.2
A8: =crop!A8 -> Permanent soil cover | B8: =crop!B8 -> C.2.3 | D8: =6/3 -> 2 | E8: =6/3 -> 2 | F8: =6/3 -> 2 | G8: =6/3 -> 2 | H8: =6/3 -> 2 | I8: =6/3 -> 2 | J8: 2 | K8: =6/3 -> 2 | M8: =6/3 -> 2 | O8: =6/3 -> 2 | P8: =6/3 -> 2 | Q8: =6/3 -> 2 | R8: =6/3 -> 2 | S8: =6/3 -> 2 | T8: =6/3 -> 2 | U8: 2 | V8: =6/3 -> 2 | X8: =6/3 -> 2 | AJ8: =0.42/3 -> 0.14 | AV8: =0.42/3 -> 0.14 | BK8: =0.42/3 -> 0.14 | BU8: =0.42/3 -> 0.14 | CF8: =0.42/3 -> 0.14 | CR8: =0.42/3 -> 0.14 | DD8: =0.42/3 -> 0.14 | DR8: =0.42/3 -> 0.14 | EP8: =0.42/3 -> 0.14 | FL8: =0.42/3 -> 0.14 | FX8: =0.42/3 -> 0.14 | GM8: =0.42/3 -> 0.14 | GW8: =0.42/3 -> 0.14 | HH8: =0.42/3 -> 0.14 | HT8: =0.42/3 -> 0.14 | IF8: =0.42/3 -> 0.14 | IT8: =0.42/3 -> 0.14 | JR8: =0.42/3 -> 0.14 | KS8: 0.8 | KT8: 0.8 | LI8: -0.5
A9: =crop!A9 -> Straw removal | B9: =crop!B9 -> C.3.1 | D9: =11.7+8.94 -> 20.64 | E9: =11.7+8.94 -> 20.64 | I9: =-20.64 -> -20.64 | O9: =11.7+8.94 -> 20.64 | P9: =11.7+8.94 -> 20.64 | T9: =-20.64 -> -20.64 | AI9: =0.5+0.67 -> 1.17 | AU9: =0.5+0.67 -> 1.17 | CQ9: =-(0.5+0.67) -> -1.17 | FK9: =0.5+0.67 -> 1.17 | FW9: =0.5+0.67 -> 1.17 | HS9: =-(0.5+0.67) -> -1.17 | KS9: 1.05 | KT9: 1.05
A10: =crop!A10 -> Straw left on soil | B10: =crop!B10 -> C.3.2 | D10: =9.02 -> 9.02 | E10: =9.02 -> 9.02 | I10: =-9.02 -> -9.02 | O10: =9.02 -> 9.02 | P10: =9.02 -> 9.02 | T10: =-9.02 -> -9.02 | AI10: 0.67 | AU10: 0.67 | CQ10: -0.67 | FK10: 0.67 | FW10: 0.67 | HS10: -0.67 | KS10: 0.9 | KT10: 0.9
A11: =crop!A11 -> On-farm organic fertilizers + input of mineral fertilizer | B11: =crop!B11 -> C.4.1 | D11: =2*1.56 -> 3.12 | E11: =2*1.56 -> 3.12 | F11: =2*1.56 -> 3.12 | G11: =2*1.56 -> 3.12 | H11: 1.56 | I11: =-2*1.56 -> -3.12 | K11: =1.56*1 -> 1.56 | M11: =1.56*1 -> 1.56 | O11: =2*1.56 -> 3.12 | P11: =2*1.56 -> 3.12 | Q11: =2*1.56 -> 3.12 | R11: =2*1.56 -> 3.12 | S11: 1.56 | T11: =-2*1.56 -> -3.12 | V11: =1.56*1 -> 1.56 | X11: =1.56*1 -> 1.56 | AF11: 0.12 | AG11: 0.12 | AR11: 0.12 | AS11: 0.12 | BC11: 0.12 | BI11: 0.12 | BP11: 0.12 | BQ11: 0.12 | BZ11: 0.12 | CN11: -0.12 | CO11: -0.12 | DM11: 0.12 | EK11: 0.12 | FH11: 0.12 | FI11: 0.12 | FT11: 0.12 | FU11: 0.12 | GE11: 0.12 | GK11: 0.12 | GR11: 0.12 | GS11: 0.12 | HB11: 0.12 | HP11: -0.12 | HQ11: -0.12 | IO11: 0.12 | JM11: 0.12 | KS11: 1.05 | KT11: 1.05
A12: =crop!A12 -> On-farm organic fertilizers only | B12: =crop!B12 -> C.4.2
A13: =crop!A13 -> Systematic use of chemical fungicides | B13: =crop!B13 -> C.5.1 | AE13: 0.11 | AF13: 0.11 | AG13: 0.11 | AR13: 0.11 | BG13: 0.11 | BH13: =0.11*2 -> 0.22 | BQ13: =2*0.11 -> 0.22 | BR13: =4*0.11 -> 0.44 | BS13: =4*0.11 -> 0.44 | BT13: =4*0.11 -> 0.44 | CB13: 0.11 | CM13: 0.11 | CN13: 0.11 | CO13: -0.11 | CZ13: 0.11 | FG13: 0.11 | FH13: 0.11 | FI13: 0.11 | FT13: 0.11 | GI13: 0.11 | GJ13: =0.11*2 -> 0.22 | GS13: =2*0.11 -> 0.22 | GT13: =4*0.11 -> 0.44 | GU13: =4*0.11 -> 0.44 | GV13: =4*0.11 -> 0.44 | HD13: 0.11 | HO13: 0.11 | HP13: 0.11 | HQ13: -0.11 | IB13: 0.11
A14: =crop!A14 -> Sound approach of chemical fungicides | B14: =crop!B14 -> C.5.2 | AE14: 0.11 | AF14: 0.11 | BG14: 0.11 | BH14: 0.11 | BQ14: 0.11 | BR14: =3*0.11 -> 0.33 | BS14: =3*0.11 -> 0.33 | BT14: =3*0.11 -> 0.33 | CM14: 0.11 | CN14: -0.11 | FG14: 0.11 | FH14: 0.11 | GI14: 0.11 | GJ14: 0.11 | GS14: 0.11 | GT14: =3*0.11 -> 0.33 | GU14: =3*0.11 -> 0.33 | GV14: =3*0.11 -> 0.33 | HO14: 0.11 | HP14: -0.11 | KS14: 0.9 | KT14: 0.9 | LI14: -0.5
A15: =crop!A15 -> Biocontrol products against diseases | B15: =crop!B15 -> C.5.3 | BH15: 0.11 | BQ15: =2*0.11 -> 0.22 | BR15: =4*0.11 -> 0.44 | BS15: =4*0.11 -> 0.44 | BT15: =4*0.11 -> 0.44 | GJ15: 0.11 | GS15: =2*0.11 -> 0.22 | GT15: =4*0.11 -> 0.44 | GU15: =4*0.11 -> 0.44 | GV15: =4*0.11 -> 0.44 | KS15: 0.85 | KT15: 0.85 | KV15: 1 | LI15: -0.5
A16: =crop!A16 -> No direct protection against diseases | B16: =crop!B16 -> C.5.4 | KS16: 0.8 | KT16: 0.8 | KV16: 1
A17: =crop!A17 -> Systematic and sole use of chemical herbicides | B17: =crop!B17 -> C.6.1 | AE17: 0.11 | AM17: 0.11 | AY17: 0.11 | BC17: 0.11 | BD17: 0.11 | BE17: 0.11 | BP17: 0.11 | BT17: =2*0.11 -> 0.22 | CA17: 0.11 | CF17: 0.11 | CU17: 0.11 | DG17: 0.11 | DL17: 0.11 | DM17: 0.11 | EC17: =0.11/2.5 -> 0.044 | EK17: 0.11 | EZ17: 0.11 | FG17: 0.11 | FO17: 0.11 | GA17: 0.11 | GE17: 0.11 | GF17: 0.11 | GG17: 0.11 | GR17: 0.11 | GV17: =2*0.11 -> 0.22 | HC17: 0.11 | HH17: 0.11 | HW17: 0.11 | II17: 0.11 | IN17: 0.11 | IO17: 0.11 | JE17: =0.11/2.5 -> 0.044 | JM17: 0.11 | KB17: 0.11
A18: =crop!A18 -> Sound approach of chemical herbicides + mechanical weed control | B18: =crop!B18 -> C.6.2 | D18: 4.95 | E18: 4.95 | F18: =2*4.95 -> 9.9 | G18: 9.02 | H18: 4.95 | I18: 4.95 | J18: =4.95*2 -> 9.9 | K18: 4.95 | L18: =K18/2.5 -> 1.98 | M18: 4.95 | N18: =K18/3 -> 1.65 | O18: 4.95 | P18: 4.95 | Q18: =2*4.95 -> 9.9 | R18: 9.02 | S18: 4.95 | T18: 4.95 | U18: =4.95*2 -> 9.9 | V18: 4.95 | W18: =V18/2.5 -> 1.98 | X18: 4.95 | Y18: =V18/3 -> 1.65 | AE18: 0.11 | AM18: 0.33 | AQ18: 0.11 | AY18: 0.33 | BC18: 0.11 | BD18: =0.11+0.33 -> 0.44 | BE18: 0.33 | BP18: 0.11 | BT18: 0.67 | CA18: 0.11 | CF18: 0.33 | CM18: 0.11 | CU18: 0.33 | CY18: 0.33 | DG18: 0.33 | DM18: =0.33+0.11 -> 0.44 | EC18: =0.33/2.5 -> 0.132 | EK18: 0.33 | FG18: 0.11 | FO18: 0.33 | FS18: 0.11 | GA18: 0.33 | GE18: 0.11 | GF18: =0.11+0.33 -> 0.44 | GG18: 0.33 | GR18: 0.11 | GV18: 0.67 | HC18: 0.11 | HH18: 0.33 | HO18: 0.11 | HW18: 0.33 | IA18: 0.33 | II18: 0.33 | IO18: =0.33+0.11 -> 0.44 | JE18: =0.33/2.5 -> 0.132 | JM18: 0.33 | KS18: 0.9 | KT18: 0.9 | KV18: 1 | LI18: -0.25
A19: =crop!A19 -> Sole use of mechanical weed control | B19: =crop!B19 -> C.6.3 | D19: =4.95*2 -> 9.9 | E19: =4.95*2 -> 9.9 | F19: =3*4.95 -> 14.85 | G19: =4.95+9.02 -> 13.97 | H19: =4.95*2 -> 9.9 | I19: =4.95*2 -> 9.9 | J19: =4.95*2 -> 9.9 | K19: =4.95*2 -> 9.9 | L19: =K19/2/2.5 -> 1.98 | M19: 4.95 | N19: =K19/2/3 -> 1.65 | O19: =4.95*2 -> 9.9 | P19: =4.95*2 -> 9.9 | Q19: =3*4.95 -> 14.85 | R19: =4.95+9.02 -> 13.97 | S19: =4.95*2 -> 9.9 | T19: =4.95*2 -> 9.9 | U19: =4.95*2 -> 9.9 | V19: =4.95*2 -> 9.9 | W19: =V19/2/2.5 -> 1.98 | X19: 4.95 | Y19: =V19/2/3 -> 1.65 | AE19: 0.33 | AM19: 0.33 | AQ19: 0.33 | AY19: 0.33 | BC19: 0.33 | BD19: 0.33 | BE19: 0.33 | BQ19: 0.33 | BT19: 0.67 | CA19: 0.33 | CF19: 0.33 | CM19: 0.33 | CU19: 0.33 | CY19: 0.33 | DG19: 0.33 | DL19: 0.33 | DM19: 0.33 | EC19: =0.33/2.5 -> 0.132 | EK19: 0.33 | FG19: 0.33 | FO19: 0.33 | FS19: 0.33 | GA19: 0.33 | GE19: 0.33 | GF19: 0.33 | GG19: 0.33 | GS19: 0.33 | GV19: 0.67 | HC19: 0.33 | HH19: 0.33 | HO19: 0.33 | HW19: 0.33 | IA19: 0.33 | II19: 0.33 | IN19: 0.33 | IO19: 0.33 | JE19: =0.33/2.5 -> 0.132 | JM19: 0.33 | KS19: 1.1 | KT19: 1.1 | KV19: 1 | LI19: -0.5
